Workbook

Sheet MainSheet
R1: Ran He | T1: Ran He | V1: Ran He | X1: Ran He | Z1: Ran He | AB1: Ran He | AD1: Ran He | AF1: Ran He | AH1: Ran He | AJ1: Ran He | AL1: Ran He | AN1: Ran He | AP1: Ran He | AR1: Ran He | AT1: Ran He | AV1: Ran He | AX1: Ran He | AZ1: Ran He | BB1: Ran He | BD1: Ran He | BF1: Ran He | BH1: Ran He | BJ1: Ran He | BL1: Ran He | BN1: Ran He | BP1: Ran He | BR1: Ran He | BT1: Ran He | BV1: Ran He | BX1: Ran He | BZ1: Ran He | CB1: Ran He | CD1: Ran He | CF1: Ran He | CH1: Ran He | CJ1: Ran He | CL1: Ran He | CN1: Ran He | CP1: Ran He | CR1: Ran He | CT1: Ran He | CV1: Ran He | CX1: Ran He | CZ1: Ran He | DB1: Ran He
R2: Yuanyuan Shi | T2: Yuanyuan Shi | V2: Yuanyuan Shi | X2: Yuanyuan Shi | Z2: Yuanyuan Shi | AB2: Yuanyuan Shi | AD2: Yuanyuan Shi | AF2: Yuanyuan Shi | AH2: Yuanyuan Shi | AJ2: Yuanyuan Shi | AL2: Yuanyuan Shi | AN2: Yuanyuan Shi | AP2: Yuanyuan Shi | AR2: Yuanyuan Shi | AT2: Yuanyuan Shi | AV2: Yuanyuan Shi | AX2: Yuanyuan Shi | AZ2: Yuanyuan Shi | BB2: Yuanyuan Shi | BD2: Yuanyuan Shi | BF2: Yuanyuan Shi | BH2: Yuanyuan Shi | BJ2: Yuanyuan Shi | BL2: Yuanyuan Shi | BN2: Yuanyuan Shi | BP2: Yuanyuan Shi | BR2: Yuanyuan Shi | BT2: Yuanyuan Shi | BV2: Yuanyuan Shi | BX2: Yuanyuan Shi | BZ2: Yuanyuan Shi | CB2: Yuanyuan Shi | CD2: Yuanyuan Shi | CF2: Yuanyuan Shi | CH2: Yuanyuan Shi | CJ2: Yuanyuan Shi | CL2: Yuanyuan Shi | CN2: Yuanyuan Shi | CP2: Yuanyuan Shi | CR2: Yuanyuan Shi | CT2: Yuanyuan Shi | CV2: Yuanyuan Shi | CX2: Yuanyuan Shi | CZ2: Yuanyuan Shi | DB2: Yuanyuan Shi
R3: A. Abbasi | T3: A. Abbasi | V3: A. Abbasi | X3: A. Abbasi | Z3: A. Abbasi | AB3: A. Abbasi | AD3: A. Abbasi | AF3: A. Abbasi | AH3: A. Abbasi | AJ3: A. Abbasi | AL3: A. Abbasi | AN3: A. Abbasi | AP3: A. Abbasi | AR3: A. Abbasi | AT3: A. Abbasi | AV3: A. Abbasi | AX3: A. Abbasi | AZ3: A. Abbasi | BB3: A. Abbasi | BD3: A. Abbasi | BF3: A. Abbasi | BH3: A. Abbasi | BJ3: A. Abbasi | BL3: A. Abbasi | BN3: A. Abbasi | BP3: A. Abbasi | BR3: A. Abbasi | BT3: A. Abbasi | BV3: A. Abbasi | BX3: A. Abbasi | BZ3: A. Abbasi | CB3: A. Abbasi | CD3: A. Abbasi | CF3: A. Abbasi | CH3: A. Abbasi | CJ3: A. Abbasi | CL3: A. Abbasi | CN3: A. Abbasi | CP3: A. Abbasi | CR3: A. Abbasi | CT3: A. Abbasi | CV3: A. Abbasi | CX3: A. Abbasi | CZ3: A. Abbasi | DB3: A. Abbasi
R4: A. Abts | T4: A. Abts | V4: A. Abts | X4: A. Abts | Z4: A. Abts | AB4: A. Abts | AD4: A. Abts | AF4: A. Abts | AH4: A. Abts | AJ4: A. Abts | AL4: A. Abts | AN4: A. Abts | AP4: A. Abts | AR4: A. Abts | AT4: A. Abts | AV4: A. Abts | AX4: A. Abts | AZ4: A. Abts | BB4: A. Abts | BD4: A. Abts | BF4: A. Abts | BH4: A. Abts | BJ4: A. Abts | BL4: A. Abts | BN4: A. Abts | BP4: A. Abts | BR4: A. Abts | BT4: A. Abts | BV4: A. Abts | BX4: A. Abts | BZ4: A. Abts | CB4: A. Abts | CD4: A. Abts | CF4: A. Abts | CH4: A. Abts | CJ4: A. Abts | CL4: A. Abts | CN4: A. Abts | CP4: A. Abts | CR4: A. Abts | CT4: A. Abts | CV4: A. Abts | CX4: A. Abts | CZ4: A. Abts | DB4: A. Abts
R5: A. Al-Ashouri | T5: A. Al-Ashouri | V5: A. Al-Ashouri | X5: A. Al-Ashouri | Z5: A. Al-Ashouri | AB5: A. Al-Ashouri | AD5: A. Al-Ashouri | AF5: A. Al-Ashouri | AH5: A. Al-Ashouri | AJ5: A. Al-Ashouri | AL5: A. Al-Ashouri | AN5: A. Al-Ashouri | AP5: A. Al-Ashouri | AR5: A. Al-Ashouri | AT5: A. Al-Ashouri | AV5: A. Al-Ashouri | AX5: A. Al-Ashouri | AZ5: A. Al-Ashouri | BB5: A. Al-Ashouri | BD5: A. Al-Ashouri | BF5: A. Al-Ashouri | BH5: A. Al-Ashouri | BJ5: A. Al-Ashouri | BL5: A. Al-Ashouri | BN5: A. Al-Ashouri | BP5: A. Al-Ashouri | BR5: A. Al-Ashouri | BT5: A. Al-Ashouri | BV5: A. Al-Ashouri | BX5: A. Al-Ashouri | BZ5: A. Al-Ashouri | CB5: A. Al-Ashouri | CD5: A. Al-Ashouri | CF5: A. Al-Ashouri | CH5: A. Al-Ashouri | CJ5: A. Al-Ashouri | CL5: A. Al-Ashouri | CN5: A. Al-Ashouri | CP5: A. Al-Ashouri | CR5: A. Al-Ashouri | CT5: A. Al-Ashouri | CV5: A. Al-Ashouri | CX5: A. Al-Ashouri | CZ5: A. Al-Ashouri | DB5: A. Al-Ashouri
R6: A. Al-Sawalmih | T6: A. Al-Sawalmih | V6: A. Al-Sawalmih | X6: A. Al-Sawalmih | Z6: A. Al-Sawalmih | AB6: A. Al-Sawalmih | AD6: A. Al-Sawalmih | AF6: A. Al-Sawalmih | AH6: A. Al-Sawalmih | AJ6: A. Al-Sawalmih | AL6: A. Al-Sawalmih | AN6: A. Al-Sawalmih | AP6: A. Al-Sawalmih | AR6: A. Al-Sawalmih | AT6: A. Al-Sawalmih | AV6: A. Al-Sawalmih | AX6: A. Al-Sawalmih | AZ6: A. Al-Sawalmih | BB6: A. Al-Sawalmih | BD6: A. Al-Sawalmih | BF6: A. Al-Sawalmih | BH6: A. Al-Sawalmih | BJ6: A. Al-Sawalmih | BL6: A. Al-Sawalmih | BN6: A. Al-Sawalmih | BP6: A. Al-Sawalmih | BR6: A. Al-Sawalmih | BT6: A. Al-Sawalmih | BV6: A. Al-Sawalmih | BX6: A. Al-Sawalmih | BZ6: A. Al-Sawalmih | CB6: A. Al-Sawalmih | CD6: A. Al-Sawalmih | CF6: A. Al-Sawalmih | CH6: A. Al-Sawalmih | CJ6: A. Al-Sawalmih | CL6: A. Al-Sawalmih | CN6: A. Al-Sawalmih | CP6: A. Al-Sawalmih | CR6: A. Al-Sawalmih | CT6: A. Al-Sawalmih | CV6: A. Al-Sawalmih | CX6: A. Al-Sawalmih | CZ6: A. Al-Sawalmih | DB6: A. Al-Sawalmih
R7: A. Alanen | T7: A. Alanen | V7: A. Alanen | X7: A. Alanen | Z7: A. Alanen | AB7: A. Alanen | AD7: A. Alanen | AF7: A. Alanen | AH7: A. Alanen | AJ7: A. Alanen | AL7: A. Alanen | AN7: A. Alanen | AP7: A. Alanen | AR7: A. Alanen | AT7: A. Alanen | AV7: A. Alanen | AX7: A. Alanen | AZ7: A. Alanen | BB7: A. Alanen | BD7: A. Alanen | BF7: A. Alanen | BH7: A. Alanen | BJ7: A. Alanen | BL7: A. Alanen | BN7: A. Alanen | BP7: A. Alanen | BR7: A. Alanen | BT7: A. Alanen | BV7: A. Alanen | BX7: A. Alanen | BZ7: A. Alanen | CB7: A. Alanen | CD7: A. Alanen | CF7: A. Alanen | CH7: A. Alanen | CJ7: A. Alanen | CL7: A. Alanen | CN7: A. Alanen | CP7: A. Alanen | CR7: A. Alanen | CT7: A. Alanen | CV7: A. Alanen | CX7: A. Alanen | CZ7: A. Alanen | DB7: A. Alanen
R8: A. Alkauskas | T8: A. Alkauskas | V8: A. Alkauskas | X8: A. Alkauskas | Z8: A. Alkauskas | AB8: A. Alkauskas | AD8: A. Alkauskas | AF8: A. Alkauskas | AH8: A. Alkauskas | AJ8: A. Alkauskas | AL8: A. Alkauskas | AN8: A. Alkauskas | AP8: A. Alkauskas | AR8: A. Alkauskas | AT8: A. Alkauskas | AV8: A. Alkauskas | AX8: A. Alkauskas | AZ8: A. Alkauskas | BB8: A. Alkauskas | BD8: A. Alkauskas | BF8: A. Alkauskas | BH8: A. Alkauskas | BJ8: A. Alkauskas | BL8: A. Alkauskas | BN8: A. Alkauskas | BP8: A. Alkauskas | BR8: A. Alkauskas | BT8: A. Alkauskas | BV8: A. Alkauskas | BX8: A. Alkauskas | BZ8: A. Alkauskas | CB8: A. Alkauskas | CD8: A. Alkauskas | CF8: A. Alkauskas | CH8: A. Alkauskas | CJ8: A. Alkauskas | CL8: A. Alkauskas | CN8: A. Alkauskas | CP8: A. Alkauskas | CR8: A. Alkauskas | CT8: A. Alkauskas | CV8: A. Alkauskas | CX8: A. Alkauskas | CZ8: A. Alkauskas | DB8: A. Alkauskas
R9: A. Ardehali Barani | T9: A. Ardehali Barani | V9: A. Ardehali Barani | X9: A. Ardehali Barani | Z9: A. Ardehali Barani | AB9: A. Ardehali Barani | AD9: A. Ardehali Barani | AF9: A. Ardehali Barani | AH9: A. Ardehali Barani | AJ9: A. Ardehali Barani | AL9: A. Ardehali Barani | AN9: A. Ardehali Barani | AP9: A. Ardehali Barani | AR9: A. Ardehali Barani | AT9: A. Ardehali Barani | AV9: A. Ardehali Barani | AX9: A. Ardehali Barani | AZ9: A. Ardehali Barani | BB9: A. Ardehali Barani | BD9: A. Ardehali Barani | BF9: A. Ardehali Barani | BH9: A. Ardehali Barani | BJ9: A. Ardehali Barani | BL9: A. Ardehali Barani | BN9: A. Ardehali Barani | BP9: A. Ardehali Barani | BR9: A. Ardehali Barani | BT9: A. Ardehali Barani | BV9: A. Ardehali Barani | BX9: A. Ardehali Barani | BZ9: A. Ardehali Barani | CB9: A. Ardehali Barani | CD9: A. Ardehali Barani | CF9: A. Ardehali Barani | CH9: A. Ardehali Barani | CJ9: A. Ardehali Barani | CL9: A. Ardehali Barani | CN9: A. Ardehali Barani | CP9: A. Ardehali Barani | CR9: A. Ardehali Barani | CT9: A. Ardehali Barani | CV9: A. Ardehali Barani | CX9: A. Ardehali Barani | CZ9: A. Ardehali Barani | DB9: A. Ardehali Barani
R10: A. Babich | T10: A. Babich | V10: A. Babich | X10: A. Babich | Z10: A. Babich | AB10: A. Babich | AD10: A. Babich | AF10: A. Babich | AH10: A. Babich | AJ10: A. Babich | AL10: A. Babich | AN10: A. Babich | AP10: A. Babich | AR10: A. Babich | AT10: A. Babich | AV10: A. Babich | AX10: A. Babich | AZ10: A. Babich | BB10: A. Babich | BD10: A. Babich | BF10: A. Babich | BH10: A. Babich | BJ10: A. Babich | BL10: A. Babich | BN10: A. Babich | BP10: A. Babich | BR10: A. Babich | BT10: A. Babich | BV10: A. Babich | BX10: A. Babich | BZ10: A. Babich | CB10: A. Babich | CD10: A. Babich | CF10: A. Babich | CH10: A. Babich | CJ10: A. Babich | CL10: A. Babich | CN10: A. Babich | CP10: A. Babich | CR10: A. Babich | CT10: A. Babich | CV10: A. Babich | CX10: A. Babich | CZ10: A. Babich | DB10: A. Babich
R11: A. Barani | T11: A. Barani | V11: A. Barani | X11: A. Barani | Z11: A. Barani | AB11: A. Barani | AD11: A. Barani | AF11: A. Barani | AH11: A. Barani | AJ11: A. Barani | AL11: A. Barani | AN11: A. Barani | AP11: A. Barani | AR11: A. Barani | AT11: A. Barani | AV11: A. Barani | AX11: A. Barani | AZ11: A. Barani | BB11: A. Barani | BD11: A. Barani | BF11: A. Barani | BH11: A. Barani | BJ11: A. Barani | BL11: A. Barani | BN11: A. Barani | BP11: A. Barani | BR11: A. Barani | BT11: A. Barani | BV11: A. Barani | BX11: A. Barani | BZ11: A. Barani | CB11: A. Barani | CD11: A. Barani | CF11: A. Barani | CH11: A. Barani | CJ11: A. Barani | CL11: A. Barani | CN11: A. Barani | CP11: A. Barani | CR11: A. Barani | CT11: A. Barani | CV11: A. Barani | CX11: A. Barani | CZ11: A. Barani | DB11: A. Barani
R12: A. Bastos | T12: A. Bastos | V12: A. Bastos | X12: A. Bastos | Z12: A. Bastos | AB12: A. Bastos | AD12: A. Bastos | AF12: A. Bastos | AH12: A. Bastos | AJ12: A. Bastos | AL12: A. Bastos | AN12: A. Bastos | AP12: A. Bastos | AR12: A. Bastos | AT12: A. Bastos | AV12: A. Bastos | AX12: A. Bastos | AZ12: A. Bastos | BB12: A. Bastos | BD12: A. Bastos | BF12: A. Bastos | BH12: A. Bastos | BJ12: A. Bastos | BL12: A. Bastos | BN12: A. Bastos | BP12: A. Bastos | BR12: A. Bastos | BT12: A. Bastos | BV12: A. Bastos | BX12: A. Bastos | BZ12: A. Bastos | CB12: A. Bastos | CD12: A. Bastos | CF12: A. Bastos | CH12: A. Bastos | CJ12: A. Bastos | CL12: A. Bastos | CN12: A. Bastos | CP12: A. Bastos | CR12: A. Bastos | CT12: A. Bastos | CV12: A. Bastos | CX12: A. Bastos | CZ12: A. Bastos | DB12: A. Bastos
... R8016: Šárka Msallamová | T8016: Šárka Msallamová | V8016: Šárka Msallamová | X8016: Šárka Msallamová | Z8016: Šárka Msallamová | AB8016: Šárka Msallamová | AD8016: Šárka Msallamová | AF8016: Šárka Msallamová | AH8016: Šárka Msallamová | AJ8016: Šárka Msallamová | AL8016: Šárka Msallamová | AN8016: Šárka Msallamová | AP8016: Šárka Msallamová | AR8016: Šárka Msallamová | AT8016: Šárka Msallamová | AV8016: Šárka Msallamová | AX8016: Šárka Msallamová | AZ8016: Šárka Msallamová | BB8016: Šárka Msallamová | BD8016: Šárka Msallamová | BF8016: Šárka Msallamová | BH8016: Šárka Msallamová | BJ8016: Šárka Msallamová | BL8016: Šárka Msallamová | BN8016: Šárka Msallamová | BP8016: Šárka Msallamová | BR8016: Šárka Msallamová | BT8016: Šárka Msallamová | BV8016: Šárka Msallamová | BX8016: Šárka Msallamová | BZ8016: Šárka Msallamová | CB8016: Šárka Msallamová | CD8016: Šárka Msallamová | CF8016: Šárka Msallamová | CH8016: Šárka Msallamová | CJ8016: Šárka Msallamová | CL8016: Šárka Msallamová | CN8016: Šárka Msallamová | CP8016: Šárka Msallamová | CR8016: Šárka Msallamová | CT8016: Šárka Msallamová | CV8016: Šárka Msallamová | CX8016: Šárka Msallamová | CZ8016: Šárka Msallamová | DB8016: Šárka Msallamová
A8017: Please try to avoid copy-pasting in areas with dropdowns, as this will break the underlying data validation and make subsequent editing difficult.
A8018: Only do so if you are sure you won't have to change the author name or affiliations afterwards, e.g. when pasting from identical sections from previous entries.
S8021: ▼ Common MPI Affiliations | U8021: ▼ Common MPI Affiliations | W8021: ▼ Common MPI Affiliations | Y8021: ▼ Common MPI Affiliations | AA8021: ▼ Common MPI Affiliations | AC8021: ▼ Common MPI Affiliations | AE8021: ▼ Common MPI Affiliations | AG8021: ▼ Common MPI Affiliations | AI8021: ▼ Common MPI Affiliations | AK8021: ▼ Common MPI Affiliations | AM8021: ▼ Common MPI Affiliations | AO8021: ▼ Common MPI Affiliations | AQ8021: ▼ Common MPI Affiliations | AS8021: ▼ Common MPI Affiliations | AU8021: ▼ Common MPI Affiliations | AW8021: ▼ Common MPI Affiliations | AY8021: ▼ Common MPI Affiliations | BA8021: ▼ Common MPI Affiliations | BC8021: ▼ Common MPI Affiliations | BE8021: ▼ Common MPI Affiliations | BG8021: ▼ Common MPI Affiliations | BI8021: ▼ Common MPI Affiliations | BK8021: ▼ Common MPI Affiliations | BM8021: ▼ Common MPI Affiliations | BO8021: ▼ Common MPI Affiliations | BQ8021: ▼ Common MPI Affiliations | BS8021: ▼ Common MPI Affiliations | BU8021: ▼ Common MPI Affiliations | BW8021: ▼ Common MPI Affiliations | BY8021: ▼ Common MPI Affiliations | CA8021: ▼ Common MPI Affiliations | CC8021: ▼ Common MPI Affiliations | CE8021: ▼ Common MPI Affiliations | CG8021: ▼ Common MPI Affiliations | CI8021: ▼ Common MPI Affiliations | CK8021: ▼ Common MPI Affiliations | CM8021: ▼ Common MPI Affiliations | CO8021: ▼ Common MPI Affiliations | CQ8021: ▼ Common MPI Affiliations | CS8021: ▼ Common MPI Affiliations | CU8021: ▼ Common MPI Affiliations | CW8021: ▼ Common MPI Affiliations | CY8021: ▼ Common MPI Affiliations | DA8021: ▼ Common MPI Affiliations | DC8021: ▼ Common MPI Affiliations
A8022: Entry Number | B8022: Title | C8022: Journal Title | D8022: Publisher | E8022: Issue | F8022: Volume | G8022: Page | H8022: Article Number | I8022: ISSN | J8022: Date published online | K8022: Date issued | L8022: DOI | M8022: License url | N8022: License year | O8022: Pdf found | P8022: Crossref Link | Q8022: Scopus Link | R8022: Author 1 | S8022: Affiliation 1 | T8022: Author 2 | U8022: Affiliation 2 | V8022: Author 3 | W8022: Affiliation 3 | X8022: Author 4 | Y8022: Affiliation 4 | Z8022: Author 5 | AA8022: Affiliation 5 | AB8022: Author 6 | AC8022: Affiliation 6 | AD8022: Author 7 | AE8022: Affiliation 7 | AF8022: Author 8 | AG8022: Affiliation 8 | AH8022: Author 9 | AI8022: Affiliation 9 | AJ8022: Author 10 | AK8022: Affiliation 10 | AL8022: Author 11 | AM8022: Affiliation 11 | AN8022: Author 12 | AO8022: Affiliation 12 | AP8022: Author 13 | AQ8022: Affiliation 13 | AR8022: Author 14 | AS8022: Affiliation 14 | AT8022: Author 15 | AU8022: Affiliation 15 | AV8022: Author 16 | AW8022: Affiliation 16 | AX8022: Author 17 | AY8022: Affiliation 17 | AZ8022: Author 18 | BA8022: Affiliation 18 | BB8022: Author 19 | BC8022: Affiliation 19 | BD8022: Author 20 | BE8022: Affiliation 20 | BF8022: Author 21 | BG8022: Affiliation 21 | BH8022: Author 22 | BI8022: Affiliation 22 | BJ8022: Author 23 | BK8022: Affiliation 23 | BL8022: Author 24 | BM8022: Affiliation 24 | BN8022: Author 25 | BO8022: Affiliation 25 | BP8022: Author 26 | BQ8022: Affiliation 26 | BR8022: Author 27 | BS8022: Affiliation 27 | BT8022: Author 28 | BU8022: Affiliation 28 | BV8022: Author 29 | BW8022: Affiliation 29 | BX8022: Author 30 | BY8022: Affiliation 30 | BZ8022: Author 31 | CA8022: Affiliation 31 | CB8022: Author 32 | CC8022: Affiliation 32 | CD8022: Author 33 | CE8022: Affiliation 33 | CF8022: Author 34 | CG8022: Affiliation 34 | CH8022: Author 35 | CI8022: Affiliation 35 | CJ8022: Author 36 | CK8022: Affiliation 36 | CL8022: Author 37 | CM8022: Affiliation 37 | CN8022: Author 38 | CO8022: Affiliation 38 | CP8022: Author 39 | CQ8022: Affiliation 39 | CR8022: Author 40 | CS8022: Affiliation 40 | CT8022: Author 41 | CU8022: Affiliation 41 | CV8022: Author 42 | CW8022: Affiliation 42 | CX8022: Author 43 | CY8022: Affiliation 43 | CZ8022: Author 44 | DA8022: Affiliation 44 | DB8022: Author 45 | DC8022: Affiliation 45 | DD8022: Helper 1 | DE8022: Helper 2 | DF8022: Helper 3 | DG8022: Helper 4 | DH8022: Helper 5 | DI8022: Helper 6 | DJ8022: Helper 7 | DK8022: Helper 8 | DL8022: Helper 9 | DM8022: Helper 10 | DN8022: Helper 11 | DO8022: Helper 12 | DP8022: Helper 13 | DQ8022: Helper 14 | DR8022: Helper 15 | DS8022: Helper 16 | DT8022: Helper 17 | DU8022: Helper 18 | DV8022: Helper 19 | DW8022: Helper 20 | DX8022: Helper 21 | DY8022: Helper 22 | DZ8022: Helper 23 | EA8022: Helper 24 | EB8022: Helper 25 | EC8022: Helper 26 | ED8022: Helper 27 | EE8022: Helper 28 | EF8022: Helper 29 | EG8022: Helper 30 | EH8022: Helper 31 | EI8022: Helper 32 | EJ8022: Helper 33 | EK8022: Helper 34 | EL8022: Helper 35 | EM8022: Helper 36 | EN8022: Helper 37 | EO8022: Helper 38 | EP8022: Helper 39 | EQ8022: Helper 40 | ER8022: Helper 41 | ES8022: Helper 42 | ET8022: Helper 43 | EU8022: Helper 44 | EV8022: Helper 45
A8023: 1 | B8023: APT Calibrator: A Multifunctional C# Software Application for Reconstruction Calibration in Atom Probe Tomography | C8023: Microscopy and Microanalysis | D8023: Oxford University Press (OUP) | E8023: 5 | F8023: 31 | H8023: ozaf092 | I8023: 1431-9276 | K8023: 3.9.2025 | L8023: 10.1093/mam/ozaf092 | M8023: https://creativecommons.org/licenses/by/4.0/ | N8023: 2025 | O8023: n | P8023: https://academic.oup.com/mam/article/doi/10.1093/mam/ozaf092/8287635 | R8023: Xinren Chen | S8023: Computational Sustainable Metallurgy, Microstructure Physics and Alloy Design, Max Planck Institute for Sustainable Materials, Max Planck Society | T8023: Yue Li | U8023: Atom Probe Tomography, Microstructure Physics and Alloy Design, Max Planck Institute for Sustainable Materials, Max Planck Society | V8023: Eric Woods | W8023: Atom Probe Tomography, Microstructure Physics and Alloy Design, Max Planck Institute for Sustainable Materials, Max Planck Society | X8023: Xuyang Zhou | Y8023: Atom Probe Tomography, Microstructure Physics and Alloy Design, Max Planck Institute for Sustainable Materials, Max Planck Society | Z8023: Baptiste Gault | AA8023: Atom Probe Tomography, Microstructure Physics and Alloy Design, Max Planck Institute for Sustainable Materials, Max Planck Society | AB8023: Baptiste Gault | AC8023: Department of Materials, Royal School of Mines, Imperial College, Prince Consort Road, London, SW7 2BP, United Kingdom | DD8023: =MATCH(R8023, Names!$A$2:$A$8017, 0) + 1 -> 7574 | DE8023: =MATCH(T8023, Names!$A$2:$A$8017, 0) + 1 -> 7803 | DF8023: =MATCH(V8023, Names!$A$2:$A$8017, 0) + 1 -> 1914 | DG8023: =MATCH(X8023, Names!$A$2:$A$8017, 0) + 1 -> 7606 | DH8023: =MATCH(Z8023, Names!$A$2:$A$8017, 0) + 1 -> 773 | DI8023: =MATCH(AB8023, Names!$A$2:$A$8017, 0) + 1 -> 773 | DJ8023: =MATCH(AD8023, Names!$A$2:$A$8017, 0) + 1 -> #N/A | DK8023: =MATCH(AF8023, Names!$A$2:$A$8017, 0) + 1 -> #N/A | DL8023: =MATCH(AH8023, Names!$A$2:$A$8017, 0) + 1 -> #N/A | DM8023: =MATCH(AJ8023, Names!$A$2:$A$8017, 0) + 1 -> #N/A | DN8023: =MATCH(AL8023, Names!$A$2:$A$8017, 0) + 1 -> #N/A | DO8023: =MATCH(AN8023, Names!$A$2:$A$8017, 0) + 1 -> #N/A | DP8023: =MATCH(AP8023, Names!$A$2:$A$8017, 0) + 1 -> #N/A | DQ8023: =MATCH(AR8023, Names!$A$2:$A$8017, 0) + 1 -> #N/A | DR8023: =MATCH(AT8023, Names!$A$2:$A$8017, 0) + 1 -> #N/A | DS8023: =MATCH(AV8023, Names!$A$2:$A$8017, 0) + 1 -> #N/A | DT8023: =MATCH(AX8023, Names!$A$2:$A$8017, 0) + 1 -> #N/A | DU8023: =MATCH(AZ8023, Names!$A$2:$A$8017, 0) + 1 -> #N/A | DV8023: =MATCH(BB8023, Names!$A$2:$A$8017, 0) + 1 -> #N/A | DW8023: =MATCH(BD8023, Names!$A$2:$A$8017, 0) + 1 -> #N/A | DX8023: =MATCH(BF8023, Names!$A$2:$A$8017, 0) + 1 -> #N/A | DY8023: =MATCH(BH8023, Names!$A$2:$A$8017, 0) + 1 -> #N/A | DZ8023: =MATCH(BJ8023, Names!$A$2:$A$8017, 0) + 1 -> #N/A | EA8023: =MATCH(BL8023, Names!$A$2:$A$8017, 0) + 1 -> #N/A | EB8023: =MATCH(BN8023, Names!$A$2:$A$8017, 0) + 1 -> #N/A | EC8023: =MATCH(BP8023, Names!$A$2:$A$8017, 0) + 1 -> #N/A | ED8023: =MATCH(BR8023, Names!$A$2:$A$8017, 0) + 1 -> #N/A | EE8023: =MATCH(BT8023, Names!$A$2:$A$8017, 0) + 1 -> #N/A | EF8023: =MATCH(BV8023, Names!$A$2:$A$8017, 0) + 1 -> #N/A | EG8023: =MATCH(BX8023, Names!$A$2:$A$8017, 0) + 1 -> #N/A | EH8023: =MATCH(BZ8023, Names!$A$2:$A$8017, 0) + 1 -> #N/A | EI8023: =MATCH(CB8023, Names!$A$2:$A$8017, 0) + 1 -> #N/A | EJ8023: =MATCH(CD8023, Names!$A$2:$A$8017, 0) + 1 -> #N/A | EK8023: =MATCH(CF8023, Names!$A$2:$A$8017, 0) + 1 -> #N/A | EL8023: =MATCH(CH8023, Names!$A$2:$A$8017, 0) + 1 -> #N/A | EM8023: =MATCH(CJ8023, Names!$A$2:$A$8017, 0) + 1 -> #N/A | EN8023: =MATCH(CL8023, Names!$A$2:$A$8017, 0) + 1 -> #N/A | EO8023: =MATCH(CN8023, Names!$A$2:$A$8017, 0) + 1 -> #N/A | EP8023: =MATCH(CP8023, Names!$A$2:$A$8017, 0) + 1 -> #N/A | EQ8023: =MATCH(CR8023, Names!$A$2:$A$8017, 0) + 1 -> #N/A | ER8023: =MATCH(CT8023, Names!$A$2:$A$8017, 0) + 1 -> #N/A | ES8023: =MATCH(CV8023, Names!$A$2:$A$8017, 0) + 1 -> #N/A | ET8023: =MATCH(CX8023, Names!$A$2:$A$8017, 0) + 1 -> #N/A | EU8023: =MATCH(CZ8023, Names!$A$2:$A$8017, 0) + 1 -> #N/A | EV8023: =MATCH(DB8023, Names!$A$2:$A$8017, 0) + 1 -> #N/A

Sheet Names
A1: Names | B1: Affiliations
A2: Ran He | B2: IFW Dresden, Helmholtzstraße20, 01069, Dresden, Germany
A3: Yuanyuan Shi | B3: Institute of Functional Nano & Soft Materials (FUNSOM), Collaborative Innovation Center of Suzhou Nanoscience and Technology, Suzhou, China | C3: Institute of Chemical Research of Catalonia (ICIQ), The Barcelona Institute of Science and Technology (BIST), Tarragona, Spain
A4: A. Abbasi | B4: External Organizations | C4: Computational Phase Studies, Computational Materials Design, Max-Planck-Institut für Eisenforschung GmbH, Max Planck Society | D4: Computational Phase Studies, Computational Materials Design, Max Planck Institute for Sustainable Materials, Max Planck Society
A5: A. Abts | B5: Electrochemistry and Corrosion, Interface Chemistry and Surface Engineering, Max-Planck-Institut für Eisenforschung GmbH, Max Planck Society | C5: Electrochemistry and Corrosion, Interface Chemistry and Surface Engineering, Max Planck Institute for Sustainable Materials, Max Planck Society
A6: A. Al-Ashouri | B6: Young Investigator Group - Perovskite Tandem Solar Cells, Helmholtz-Zentrum Berlin
A7: A. Al-Sawalmih | B7: Biological Composites, Microstructure Physics and Alloy Design, Max-Planck-Institut für Eisenforschung GmbH, Max Planck Society | C7: External Organizations | D7: Biological Composites, Microstructure Physics and Alloy Design, Max Planck Institute for Sustainable Materials, Max Planck Society
A8: A. Alanen
A9: A. Alkauskas
A10: A. Ardehali Barani | B10: Alloy Design and Thermomechanical Processing, Microstructure Physics and Alloy Design, Max-Planck-Institut für Eisenforschung GmbH, Max Planck Society | C10: External Organizations | D10: Alloy Design and Thermomechanical Processing, Microstructure Physics and Alloy Design, Max Planck Institute for Sustainable Materials, Max Planck Society
A11: A. Babich
A12: A. Barani
A13: A. Bastos
A14: A. Bergmaier
A15: A. Beskrovnyi I | B15: Laboratory of Neutron Physics, Joint Institute for Nuclear Research, Dubna, Moscow District 141980, Russia
A16: A. Blümich | B16: SENTECH Instruments GmbH, D-12489 Berlin, Germany
A17: A. Brahme | B17: Microstructure Physics and Alloy Design, Max-Planck-Institut für Eisenforschung GmbH, Max Planck Society | C17: External Organizations | D17: Microstructure Physics and Alloy Design, Max Planck Institute for Sustainable Materials, Max Planck Society
A18: A. Butz
A19: A. Carmel Mary Esther | B19: Institut für Materialphysik, Westfälische Wilhelms-Universität Münster, Wilhelms, Germany
A20: A. Chakkedah
A21: A. Chakkedath
A22: A. Chakrabarti
A23: A. Cuitino
A24: A. Dannenberg
A25: A. De Nicolo
A26: A. DeBremaecker
A27: A. Di Prinzio
A28: A. Diaz Ortiz
A29: A. Diaz-Ortiz | B29: Max Planck Society
A30: A. Dlouhy
A31: A. Dreier
A32: A. Durairajan | B32: I3N-Aveiro, Department of Physics, University of Aveiro, Aveiro 3810 193, Portugal
A33: A. Dziakova
A34: A. Egan | B34: Center for Electron Microscopy and Analysis, The Ohio State University, Columbus, OH, 43212, USA | C34: Department of Materials Science and Engineering, The Ohio State University, Columbus, OH, 43210, USA_x000D_ _x000D_ View author publicati
A35: A. Eicke
A36: A. Eisenlohr | B36: Microstructure Physics and Alloy Design, Max-Planck-Institut für Eisenforschung GmbH, Max Planck Society | C36: Microstructure Physics and Alloy Design, Max Planck Institute for Sustainable Materials, Max Planck Society
A37: A. Ektarawong | B37: Thin Film Physics Division, Department of Physics, Chemistry and Biology (IFM), Linköping University, Linköping, Sweden
A38: A. Elsner | B38: Alloy Design and Thermomechanical Processing, Microstructure Physics and Alloy Design, Max-Planck-Institut für Eisenforschung GmbH, Max Planck Society | C38: External Organizations | D38: Alloy Design and Thermomechanical Processing, Microstructure Physics and Alloy Design, Max Planck Institute for Sustainable Materials, Max Planck Society
A39: A. Engström
A40: A. Fernández
...

Sheet MPI_Affiliations
A1: Microstructure Physics and Alloy Design, Max Planck Institute for Sustainable Materials, Max Planck Society
A2: Microstructure Physics and Alloy Design, Max-Planck-Institut für Eisenforschung GmbH, Max Planck Society
A3: Atom Probe Tomography, Microstructure Physics and Alloy Design, Max Planck Institute for Sustainable Materials, Max Planck Society
A4: Atom Probe Tomography, Microstructure Physics and Alloy Design, Max-Planck-Institut für Eisenforschung GmbH, Max Planck Society
A5: Theory and Simulation, Microstructure Physics and Alloy Design, Max Planck Institute for Sustainable Materials, Max Planck Society
A6: Theory and Simulation, Microstructure Physics and Alloy Design, Max-Planck-Institut für Eisenforschung GmbH, Max Planck Society
A7: Corrosion, Interface Chemistry and Surface Engineering, Max Planck Institute for Sustainable Materials, Max Planck Society
A8: Corrosion, Interface Chemistry and Surface Engineering, Max-Planck-Institut für Eisenforschung GmbH, Max Planck Society
A9: Electrocatalysis, Interface Chemistry and Surface Engineering, Max-Planck-Institut für Eisenforschung GmbH, Max Planck Society
A10: Electrocatalysis, Interface Chemistry and Surface Engineering, Max Planck Institute for Sustainable Materials, Max Planck Society
A11: Computational Phase Studies, Computational Materials Design, Max Planck Institute for Sustainable Materials, Max Planck Society
A12: Interface Spectroscopy, Interface Chemistry and Surface Engineering, Max-Planck-Institut für Eisenforschung GmbH, Max Planck Society
... A379: Sustainable Synthesis of Materials, Interdepartmental and Partner Groups, Max-Planck-Institut for Sustainable Materials, Max Planck Society
