Workbook

Sheet MainSheet
Q1: Pallabi Bhuyan | T1: Pallabi Bhuyan | W1: Pallabi Bhuyan | Z1: Pallabi Bhuyan | AC1: Pallabi Bhuyan | AF1: Pallabi Bhuyan | AI1: Pallabi Bhuyan | AL1: Pallabi Bhuyan | AO1: Pallabi Bhuyan | AR1: Pallabi Bhuyan | AU1: Pallabi Bhuyan | AX1: Pallabi Bhuyan | BA1: Pallabi Bhuyan | BD1: Pallabi Bhuyan | BG1: Pallabi Bhuyan | BJ1: Pallabi Bhuyan | BM1: Pallabi Bhuyan | BP1: Pallabi Bhuyan | BS1: Pallabi Bhuyan | BV1: Pallabi Bhuyan | BY1: Pallabi Bhuyan | CB1: Pallabi Bhuyan | CE1: Pallabi Bhuyan | CH1: Pallabi Bhuyan | CK1: Pallabi Bhuyan | CN1: Pallabi Bhuyan | CQ1: Pallabi Bhuyan | CT1: Pallabi Bhuyan | CW1: Pallabi Bhuyan | CZ1: Pallabi Bhuyan | DC1: Pallabi Bhuyan | DF1: Pallabi Bhuyan | DI1: Pallabi Bhuyan | DL1: Pallabi Bhuyan | DO1: Pallabi Bhuyan | DR1: Pallabi Bhuyan | DU1: Pallabi Bhuyan | DX1: Pallabi Bhuyan | EA1: Pallabi Bhuyan | ED1: Pallabi Bhuyan | EG1: Pallabi Bhuyan | EJ1: Pallabi Bhuyan | EM1: Pallabi Bhuyan | EP1: Pallabi Bhuyan | ES1: Pallabi Bhuyan
Q2: Ran He | T2: Ran He | W2: Ran He | Z2: Ran He | AC2: Ran He | AF2: Ran He | AI2: Ran He | AL2: Ran He | AO2: Ran He | AR2: Ran He | AU2: Ran He | AX2: Ran He | BA2: Ran He | BD2: Ran He | BG2: Ran He | BJ2: Ran He | BM2: Ran He | BP2: Ran He | BS2: Ran He | BV2: Ran He | BY2: Ran He | CB2: Ran He | CE2: Ran He | CH2: Ran He | CK2: Ran He | CN2: Ran He | CQ2: Ran He | CT2: Ran He | CW2: Ran He | CZ2: Ran He | DC2: Ran He | DF2: Ran He | DI2: Ran He | DL2: Ran He | DO2: Ran He | DR2: Ran He | DU2: Ran He | DX2: Ran He | EA2: Ran He | ED2: Ran He | EG2: Ran He | EJ2: Ran He | EM2: Ran He | EP2: Ran He | ES2: Ran He
Q3: Yuanyuan Shi | T3: Yuanyuan Shi | W3: Yuanyuan Shi | Z3: Yuanyuan Shi | AC3: Yuanyuan Shi | AF3: Yuanyuan Shi | AI3: Yuanyuan Shi | AL3: Yuanyuan Shi | AO3: Yuanyuan Shi | AR3: Yuanyuan Shi | AU3: Yuanyuan Shi | AX3: Yuanyuan Shi | BA3: Yuanyuan Shi | BD3: Yuanyuan Shi | BG3: Yuanyuan Shi | BJ3: Yuanyuan Shi | BM3: Yuanyuan Shi | BP3: Yuanyuan Shi | BS3: Yuanyuan Shi | BV3: Yuanyuan Shi | BY3: Yuanyuan Shi | CB3: Yuanyuan Shi | CE3: Yuanyuan Shi | CH3: Yuanyuan Shi | CK3: Yuanyuan Shi | CN3: Yuanyuan Shi | CQ3: Yuanyuan Shi | CT3: Yuanyuan Shi | CW3: Yuanyuan Shi | CZ3: Yuanyuan Shi | DC3: Yuanyuan Shi | DF3: Yuanyuan Shi | DI3: Yuanyuan Shi | DL3: Yuanyuan Shi | DO3: Yuanyuan Shi | DR3: Yuanyuan Shi | DU3: Yuanyuan Shi | DX3: Yuanyuan Shi | EA3: Yuanyuan Shi | ED3: Yuanyuan Shi | EG3: Yuanyuan Shi | EJ3: Yuanyuan Shi | EM3: Yuanyuan Shi | EP3: Yuanyuan Shi | ES3: Yuanyuan Shi
Q4: A. Abbasi | T4: A. Abbasi | W4: A. Abbasi | Z4: A. Abbasi | AC4: A. Abbasi | AF4: A. Abbasi | AI4: A. Abbasi | AL4: A. Abbasi | AO4: A. Abbasi | AR4: A. Abbasi | AU4: A. Abbasi | AX4: A. Abbasi | BA4: A. Abbasi | BD4: A. Abbasi | BG4: A. Abbasi | BJ4: A. Abbasi | BM4: A. Abbasi | BP4: A. Abbasi | BS4: A. Abbasi | BV4: A. Abbasi | BY4: A. Abbasi | CB4: A. Abbasi | CE4: A. Abbasi | CH4: A. Abbasi | CK4: A. Abbasi | CN4: A. Abbasi | CQ4: A. Abbasi | CT4: A. Abbasi | CW4: A. Abbasi | CZ4: A. Abbasi | DC4: A. Abbasi | DF4: A. Abbasi | DI4: A. Abbasi | DL4: A. Abbasi | DO4: A. Abbasi | DR4: A. Abbasi | DU4: A. Abbasi | DX4: A. Abbasi | EA4: A. Abbasi | ED4: A. Abbasi | EG4: A. Abbasi | EJ4: A. Abbasi | EM4: A. Abbasi | EP4: A. Abbasi | ES4: A. Abbasi
Q5: A. Abts | T5: A. Abts | W5: A. Abts | Z5: A. Abts | AC5: A. Abts | AF5: A. Abts | AI5: A. Abts | AL5: A. Abts | AO5: A. Abts | AR5: A. Abts | AU5: A. Abts | AX5: A. Abts | BA5: A. Abts | BD5: A. Abts | BG5: A. Abts | BJ5: A. Abts | BM5: A. Abts | BP5: A. Abts | BS5: A. Abts | BV5: A. Abts | BY5: A. Abts | CB5: A. Abts | CE5: A. Abts | CH5: A. Abts | CK5: A. Abts | CN5: A. Abts | CQ5: A. Abts | CT5: A. Abts | CW5: A. Abts | CZ5: A. Abts | DC5: A. Abts | DF5: A. Abts | DI5: A. Abts | DL5: A. Abts | DO5: A. Abts | DR5: A. Abts | DU5: A. Abts | DX5: A. Abts | EA5: A. Abts | ED5: A. Abts | EG5: A. Abts | EJ5: A. Abts | EM5: A. Abts | EP5: A. Abts | ES5: A. Abts
Q6: A. Al-Ashouri | T6: A. Al-Ashouri | W6: A. Al-Ashouri | Z6: A. Al-Ashouri | AC6: A. Al-Ashouri | AF6: A. Al-Ashouri | AI6: A. Al-Ashouri | AL6: A. Al-Ashouri | AO6: A. Al-Ashouri | AR6: A. Al-Ashouri | AU6: A. Al-Ashouri | AX6: A. Al-Ashouri | BA6: A. Al-Ashouri | BD6: A. Al-Ashouri | BG6: A. Al-Ashouri | BJ6: A. Al-Ashouri | BM6: A. Al-Ashouri | BP6: A. Al-Ashouri | BS6: A. Al-Ashouri | BV6: A. Al-Ashouri | BY6: A. Al-Ashouri | CB6: A. Al-Ashouri | CE6: A. Al-Ashouri | CH6: A. Al-Ashouri | CK6: A. Al-Ashouri | CN6: A. Al-Ashouri | CQ6: A. Al-Ashouri | CT6: A. Al-Ashouri | CW6: A. Al-Ashouri | CZ6: A. Al-Ashouri | DC6: A. Al-Ashouri | DF6: A. Al-Ashouri | DI6: A. Al-Ashouri | DL6: A. Al-Ashouri | DO6: A. Al-Ashouri | DR6: A. Al-Ashouri | DU6: A. Al-Ashouri | DX6: A. Al-Ashouri | EA6: A. Al-Ashouri | ED6: A. Al-Ashouri | EG6: A. Al-Ashouri | EJ6: A. Al-Ashouri | EM6: A. Al-Ashouri | EP6: A. Al-Ashouri | ES6: A. Al-Ashouri
Q7: A. Al-Sawalmih | T7: A. Al-Sawalmih | W7: A. Al-Sawalmih | Z7: A. Al-Sawalmih | AC7: A. Al-Sawalmih | AF7: A. Al-Sawalmih | AI7: A. Al-Sawalmih | AL7: A. Al-Sawalmih | AO7: A. Al-Sawalmih | AR7: A. Al-Sawalmih | AU7: A. Al-Sawalmih | AX7: A. Al-Sawalmih | BA7: A. Al-Sawalmih | BD7: A. Al-Sawalmih | BG7: A. Al-Sawalmih | BJ7: A. Al-Sawalmih | BM7: A. Al-Sawalmih | BP7: A. Al-Sawalmih | BS7: A. Al-Sawalmih | BV7: A. Al-Sawalmih | BY7: A. Al-Sawalmih | CB7: A. Al-Sawalmih | CE7: A. Al-Sawalmih | CH7: A. Al-Sawalmih | CK7: A. Al-Sawalmih | CN7: A. Al-Sawalmih | CQ7: A. Al-Sawalmih | CT7: A. Al-Sawalmih | CW7: A. Al-Sawalmih | CZ7: A. Al-Sawalmih | DC7: A. Al-Sawalmih | DF7: A. Al-Sawalmih | DI7: A. Al-Sawalmih | DL7: A. Al-Sawalmih | DO7: A. Al-Sawalmih | DR7: A. Al-Sawalmih | DU7: A. Al-Sawalmih | DX7: A. Al-Sawalmih | EA7: A. Al-Sawalmih | ED7: A. Al-Sawalmih | EG7: A. Al-Sawalmih | EJ7: A. Al-Sawalmih | EM7: A. Al-Sawalmih | EP7: A. Al-Sawalmih | ES7: A. Al-Sawalmih
Q8: A. Alanen | T8: A. Alanen | W8: A. Alanen | Z8: A. Alanen | AC8: A. Alanen | AF8: A. Alanen | AI8: A. Alanen | AL8: A. Alanen | AO8: A. Alanen | AR8: A. Alanen | AU8: A. Alanen | AX8: A. Alanen | BA8: A. Alanen | BD8: A. Alanen | BG8: A. Alanen | BJ8: A. Alanen | BM8: A. Alanen | BP8: A. Alanen | BS8: A. Alanen | BV8: A. Alanen | BY8: A. Alanen | CB8: A. Alanen | CE8: A. Alanen | CH8: A. Alanen | CK8: A. Alanen | CN8: A. Alanen | CQ8: A. Alanen | CT8: A. Alanen | CW8: A. Alanen | CZ8: A. Alanen | DC8: A. Alanen | DF8: A. Alanen | DI8: A. Alanen | DL8: A. Alanen | DO8: A. Alanen | DR8: A. Alanen | DU8: A. Alanen | DX8: A. Alanen | EA8: A. Alanen | ED8: A. Alanen | EG8: A. Alanen | EJ8: A. Alanen | EM8: A. Alanen | EP8: A. Alanen | ES8: A. Alanen
Q9: A. Alkauskas | T9: A. Alkauskas | W9: A. Alkauskas | Z9: A. Alkauskas | AC9: A. Alkauskas | AF9: A. Alkauskas | AI9: A. Alkauskas | AL9: A. Alkauskas | AO9: A. Alkauskas | AR9: A. Alkauskas | AU9: A. Alkauskas | AX9: A. Alkauskas | BA9: A. Alkauskas | BD9: A. Alkauskas | BG9: A. Alkauskas | BJ9: A. Alkauskas | BM9: A. Alkauskas | BP9: A. Alkauskas | BS9: A. Alkauskas | BV9: A. Alkauskas | BY9: A. Alkauskas | CB9: A. Alkauskas | CE9: A. Alkauskas | CH9: A. Alkauskas | CK9: A. Alkauskas | CN9: A. Alkauskas | CQ9: A. Alkauskas | CT9: A. Alkauskas | CW9: A. Alkauskas | CZ9: A. Alkauskas | DC9: A. Alkauskas | DF9: A. Alkauskas | DI9: A. Alkauskas | DL9: A. Alkauskas | DO9: A. Alkauskas | DR9: A. Alkauskas | DU9: A. Alkauskas | DX9: A. Alkauskas | EA9: A. Alkauskas | ED9: A. Alkauskas | EG9: A. Alkauskas | EJ9: A. Alkauskas | EM9: A. Alkauskas | EP9: A. Alkauskas | ES9: A. Alkauskas
Q10: A. Ardehali Barani | T10: A. Ardehali Barani | W10: A. Ardehali Barani | Z10: A. Ardehali Barani | AC10: A. Ardehali Barani | AF10: A. Ardehali Barani | AI10: A. Ardehali Barani | AL10: A. Ardehali Barani | AO10: A. Ardehali Barani | AR10: A. Ardehali Barani | AU10: A. Ardehali Barani | AX10: A. Ardehali Barani | BA10: A. Ardehali Barani | BD10: A. Ardehali Barani | BG10: A. Ardehali Barani | BJ10: A. Ardehali Barani | BM10: A. Ardehali Barani | BP10: A. Ardehali Barani | BS10: A. Ardehali Barani | BV10: A. Ardehali Barani | BY10: A. Ardehali Barani | CB10: A. Ardehali Barani | CE10: A. Ardehali Barani | CH10: A. Ardehali Barani | CK10: A. Ardehali Barani | CN10: A. Ardehali Barani | CQ10: A. Ardehali Barani | CT10: A. Ardehali Barani | CW10: A. Ardehali Barani | CZ10: A. Ardehali Barani | DC10: A. Ardehali Barani | DF10: A. Ardehali Barani | DI10: A. Ardehali Barani | DL10: A. Ardehali Barani | DO10: A. Ardehali Barani | DR10: A. Ardehali Barani | DU10: A. Ardehali Barani | DX10: A. Ardehali Barani | EA10: A. Ardehali Barani | ED10: A. Ardehali Barani | EG10: A. Ardehali Barani | EJ10: A. Ardehali Barani | EM10: A. Ardehali Barani | EP10: A. Ardehali Barani | ES10: A. Ardehali Barani
Q11: A. Babich | T11: A. Babich | W11: A. Babich | Z11: A. Babich | AC11: A. Babich | AF11: A. Babich | AI11: A. Babich | AL11: A. Babich | AO11: A. Babich | AR11: A. Babich | AU11: A. Babich | AX11: A. Babich | BA11: A. Babich | BD11: A. Babich | BG11: A. Babich | BJ11: A. Babich | BM11: A. Babich | BP11: A. Babich | BS11: A. Babich | BV11: A. Babich | BY11: A. Babich | CB11: A. Babich | CE11: A. Babich | CH11: A. Babich | CK11: A. Babich | CN11: A. Babich | CQ11: A. Babich | CT11: A. Babich | CW11: A. Babich | CZ11: A. Babich | DC11: A. Babich | DF11: A. Babich | DI11: A. Babich | DL11: A. Babich | DO11: A. Babich | DR11: A. Babich | DU11: A. Babich | DX11: A. Babich | EA11: A. Babich | ED11: A. Babich | EG11: A. Babich | EJ11: A. Babich | EM11: A. Babich | EP11: A. Babich | ES11: A. Babich
Q12: A. Barani | T12: A. Barani | W12: A. Barani | Z12: A. Barani | AC12: A. Barani | AF12: A. Barani | AI12: A. Barani | AL12: A. Barani | AO12: A. Barani | AR12: A. Barani | AU12: A. Barani | AX12: A. Barani | BA12: A. Barani | BD12: A. Barani | BG12: A. Barani | BJ12: A. Barani | BM12: A. Barani | BP12: A. Barani | BS12: A. Barani | BV12: A. Barani | BY12: A. Barani | CB12: A. Barani | CE12: A. Barani | CH12: A. Barani | CK12: A. Barani | CN12: A. Barani | CQ12: A. Barani | CT12: A. Barani | CW12: A. Barani | CZ12: A. Barani | DC12: A. Barani | DF12: A. Barani | DI12: A. Barani | DL12: A. Barani | DO12: A. Barani | DR12: A. Barani | DU12: A. Barani | DX12: A. Barani | EA12: A. Barani | ED12: A. Barani | EG12: A. Barani | EJ12: A. Barani | EM12: A. Barani | EP12: A. Barani | ES12: A. Barani
... Q8077: Šárka Msallamová | T8077: Šárka Msallamová | W8077: Šárka Msallamová | Z8077: Šárka Msallamová | AC8077: Šárka Msallamová | AF8077: Šárka Msallamová | AI8077: Šárka Msallamová | AL8077: Šárka Msallamová | AO8077: Šárka Msallamová | AR8077: Šárka Msallamová | AU8077: Šárka Msallamová | AX8077: Šárka Msallamová | BA8077: Šárka Msallamová | BD8077: Šárka Msallamová | BG8077: Šárka Msallamová | BJ8077: Šárka Msallamová | BM8077: Šárka Msallamová | BP8077: Šárka Msallamová | BS8077: Šárka Msallamová | BV8077: Šárka Msallamová | BY8077: Šárka Msallamová | CB8077: Šárka Msallamová | CE8077: Šárka Msallamová | CH8077: Šárka Msallamová | CK8077: Šárka Msallamová | CN8077: Šárka Msallamová | CQ8077: Šárka Msallamová | CT8077: Šárka Msallamová | CW8077: Šárka Msallamová | CZ8077: Šárka Msallamová | DC8077: Šárka Msallamová | DF8077: Šárka Msallamová | DI8077: Šárka Msallamová | DL8077: Šárka Msallamová | DO8077: Šárka Msallamová | DR8077: Šárka Msallamová | DU8077: Šárka Msallamová | DX8077: Šárka Msallamová | EA8077: Šárka Msallamová | ED8077: Šárka Msallamová | EG8077: Šárka Msallamová | EJ8077: Šárka Msallamová | EM8077: Šárka Msallamová | EP8077: Šárka Msallamová | ES8077: Šárka Msallamová
A8079: Please try to avoid copy-pasting in areas with dropdowns, as this will break the underlying data validation and make subsequent editing difficult.
A8080: Only do so if you are sure you won't have to change the author name or affiliations afterwards, e.g. when pasting from identical sections from previous entries.
R8081: ▼ Common MPI Affiliations
A8082: Title | B8082: Journal Title | C8082: Publisher | D8082: Issue | E8082: Volume | F8082: Page | G8082: Article Number | H8082: ISSN | I8082: Date published online | J8082: Date issued | K8082: DOI | L8082: License url | M8082: License year | N8082: Pdf found | O8082: Crossref Link | P8082: Scopus Link | Q8082: Author 1 | R8082: Affiliation 1 | S8082: Helper 1 | T8082: Author 2 | U8082: Affiliation 2 | V8082: Helper 2 | W8082: Author 3 | X8082: Affiliation 3 | Y8082: Helper 3 | Z8082: Author 4 | AA8082: Affiliation 4 | AB8082: Helper 4 | AC8082: Author 5 | AD8082: Affiliation 5 | AE8082: Helper 5 | AF8082: Author 6 | AG8082: Affiliation 6 | AH8082: Helper 6 | AI8082: Author 7 | AJ8082: Affiliation 7 | AK8082: Helper 7 | AL8082: Author 8 | AM8082: Affiliation 8 | AN8082: Helper 8 | AO8082: Author 9 | AP8082: Affiliation 9 | AQ8082: Helper 9 | AR8082: Author 10 | AS8082: Affiliation 10 | AT8082: Helper 10 | AU8082: Author 11 | AV8082: Affiliation 11 | AW8082: Helper 11 | AX8082: Author 12 | AY8082: Affiliation 12 | AZ8082: Helper 12 | BA8082: Author 13 | BB8082: Affiliation 13 | BC8082: Helper 13 | BD8082: Author 14 | BE8082: Affiliation 14 | BF8082: Helper 14 | BG8082: Author 15 | BH8082: Affiliation 15 | BI8082: Helper 15 | BJ8082: Author 16 | BK8082: Affiliation 16 | BL8082: Helper 16 | BM8082: Author 17 | BN8082: Affiliation 17 | BO8082: Helper 17 | BP8082: Author 18 | BQ8082: Affiliation 18 | BR8082: Helper 18 | BS8082: Author 19 | BT8082: Affiliation 19 | BU8082: Helper 19 | BV8082: Author 20 | BW8082: Affiliation 20 | BX8082: Helper 20 | BY8082: Author 21 | BZ8082: Affiliation 21 | CA8082: Helper 21 | CB8082: Author 22 | CC8082: Affiliation 22 | CD8082: Helper 22 | CE8082: Author 23 | CF8082: Affiliation 23 | CG8082: Helper 23 | CH8082: Author 24 | CI8082: Affiliation 24 | CJ8082: Helper 24 | CK8082: Author 25 | CL8082: Affiliation 25 | CM8082: Helper 25 | CN8082: Author 26 | CO8082: Affiliation 26 | CP8082: Helper 26 | CQ8082: Author 27 | CR8082: Affiliation 27 | CS8082: Helper 27 | CT8082: Author 28 | CU8082: Affiliation 28 | CV8082: Helper 28 | CW8082: Author 29 | CX8082: Affiliation 29 | CY8082: Helper 29 | CZ8082: Author 30 | DA8082: Affiliation 30 | DB8082: Helper 30 | DC8082: Author 31 | DD8082: Affiliation 31 | DE8082: Helper 31 | DF8082: Author 32 | DG8082: Affiliation 32 | DH8082: Helper 32 | DI8082: Author 33 | DJ8082: Affiliation 33 | DK8082: Helper 33 | DL8082: Author 34 | DM8082: Affiliation 34 | DN8082: Helper 34 | DO8082: Author 35 | DP8082: Affiliation 35 | DQ8082: Helper 35 | DR8082: Author 36 | DS8082: Affiliation 36 | DT8082: Helper 36 | DU8082: Author 37 | DV8082: Affiliation 37 | DW8082: Helper 37 | DX8082: Author 38 | DY8082: Affiliation 38 | DZ8082: Helper 38 | EA8082: Author 39 | EB8082: Affiliation 39 | EC8082: Helper 39 | ED8082: Author 40 | EE8082: Affiliation 40 | EF8082: Helper 40 | EG8082: Author 41 | EH8082: Affiliation 41 | EI8082: Helper 41 | EJ8082: Author 42 | EK8082: Affiliation 42 | EL8082: Helper 42 | EM8082: Author 43 | EN8082: Affiliation 43 | EO8082: Helper 43 | EP8082: Author 44 | EQ8082: Affiliation 44 | ER8082: Helper 44 | ES8082: Author 45 | ET8082: Affiliation 45 | EU8082: Helper 45
A8083: Lithium transport from operando microscopy: Kinetic trapping in lithium manganese oxide | B8083: Nano Energy | C8083: Elsevier BV | E8083: 151 | G8083: 111797 | H8083: 2211-2855 | J8083: 5.2026 | K8083: 10.1016/j.nanoen.2026.111797 | L8083: http://creativecommons.org/licenses/by/4.0/ | M8083: 2026 | N8083: y | O8083: https://linkinghub.elsevier.com/retrieve/pii/S2211285526001011 | Q8083: Monica Mead | R8083: Institute of Materials Science, University of Stuttgart, Heisenbergstraße 3, 70569 Stuttgart, Germany | S8083: =MATCH(Q8083, Names!$A$2:$A$8078, 0) + 1 -> 5071 | T8083: Nadine Kerner | U8083: Institute of Materials Science, University of Stuttgart, Heisenbergstraße 3, 70569 Stuttgart, Germany | V8083: =MATCH(T8083, Names!$A$2:$A$8078, 0) + 1 -> 5172 | W8083: Roham Talei | X8083: Institute of Materials Science, University of Stuttgart, Heisenbergstraße 3, 70569 Stuttgart, Germany | Y8083: =MATCH(W8083, Names!$A$2:$A$8078, 0) + 1 -> 6065 | Z8083: Yug Joshi | AA8083: Microstructure and interfaces of battery materials , Microstructure Physics and Alloy Design, Max Planck Institute for Sustainable Materials, Max Planck Society | AB8083: =MATCH(Z8083, Names!$A$2:$A$8078, 0) + 1 -> 7870 | AC8083: Guido Schmitz | AD8083: Institute of Materials Science, University of Stuttgart, Heisenbergstraße 3, 70569 Stuttgart, Germany | AE8083: =MATCH(AC8083, Names!$A$2:$A$8078, 0) + 1 -> 2431 | AH8083: =MATCH(AF8083, Names!$A$2:$A$8078, 0) + 1 -> #N/A | AK8083: =MATCH(AI8083, Names!$A$2:$A$8078, 0) + 1 -> #N/A | AN8083: =MATCH(AL8083, Names!$A$2:$A$8078, 0) + 1 -> #N/A | AQ8083: =MATCH(AO8083, Names!$A$2:$A$8078, 0) + 1 -> #N/A | AT8083: =MATCH(AR8083, Names!$A$2:$A$8078, 0) + 1 -> #N/A | AW8083: =MATCH(AU8083, Names!$A$2:$A$8078, 0) + 1 -> #N/A | AZ8083: =MATCH(AX8083, Names!$A$2:$A$8078, 0) + 1 -> #N/A | BC8083: =MATCH(BA8083, Names!$A$2:$A$8078, 0) + 1 -> #N/A | BF8083: =MATCH(BD8083, Names!$A$2:$A$8078, 0) + 1 -> #N/A | BI8083: =MATCH(BG8083, Names!$A$2:$A$8078, 0) + 1 -> #N/A | BL8083: =MATCH(BJ8083, Names!$A$2:$A$8078, 0) + 1 -> #N/A | BO8083: =MATCH(BM8083, Names!$A$2:$A$8078, 0) + 1 -> #N/A | BR8083: =MATCH(BP8083, Names!$A$2:$A$8078, 0) + 1 -> #N/A | BU8083: =MATCH(BS8083, Names!$A$2:$A$8078, 0) + 1 -> #N/A | BX8083: =MATCH(BV8083, Names!$A$2:$A$8078, 0) + 1 -> #N/A | CA8083: =MATCH(BY8083, Names!$A$2:$A$8078, 0) + 1 -> #N/A | CD8083: =MATCH(CB8083, Names!$A$2:$A$8078, 0) + 1 -> #N/A | CG8083: =MATCH(CE8083, Names!$A$2:$A$8078, 0) + 1 -> #N/A | CJ8083: =MATCH(CH8083, Names!$A$2:$A$8078, 0) + 1 -> #N/A | CM8083: =MATCH(CK8083, Names!$A$2:$A$8078, 0) + 1 -> #N/A | CP8083: =MATCH(CN8083, Names!$A$2:$A$8078, 0) + 1 -> #N/A | CS8083: =MATCH(CQ8083, Names!$A$2:$A$8078, 0) + 1 -> #N/A | CV8083: =MATCH(CT8083, Names!$A$2:$A$8078, 0) + 1 -> #N/A | CY8083: =MATCH(CW8083, Names!$A$2:$A$8078, 0) + 1 -> #N/A | DB8083: =MATCH(CZ8083, Names!$A$2:$A$8078, 0) + 1 -> #N/A | DE8083: =MATCH(DC8083, Names!$A$2:$A$8078, 0) + 1 -> #N/A | DH8083: =MATCH(DF8083, Names!$A$2:$A$8078, 0) + 1 -> #N/A | DK8083: =MATCH(DI8083, Names!$A$2:$A$8078, 0) + 1 -> #N/A | DN8083: =MATCH(DL8083, Names!$A$2:$A$8078, 0) + 1 -> #N/A | DQ8083: =MATCH(DO8083, Names!$A$2:$A$8078, 0) + 1 -> #N/A | DT8083: =MATCH(DR8083, Names!$A$2:$A$8078, 0) + 1 -> #N/A | DW8083: =MATCH(DU8083, Names!$A$2:$A$8078, 0) + 1 -> #N/A | DZ8083: =MATCH(DX8083, Names!$A$2:$A$8078, 0) + 1 -> #N/A | EC8083: =MATCH(EA8083, Names!$A$2:$A$8078, 0) + 1 -> #N/A | EF8083: =MATCH(ED8083, Names!$A$2:$A$8078, 0) + 1 -> #N/A | EI8083: =MATCH(EG8083, Names!$A$2:$A$8078, 0) + 1 -> #N/A | EL8083: =MATCH(EJ8083, Names!$A$2:$A$8078, 0) + 1 -> #N/A | EO8083: =MATCH(EM8083, Names!$A$2:$A$8078, 0) + 1 -> #N/A | ER8083: =MATCH(EP8083, Names!$A$2:$A$8078, 0) + 1 -> #N/A | EU8083: =MATCH(ES8083, Names!$A$2:$A$8078, 0) + 1 -> #N/A

Sheet Names
A1: Names | B1: Affiliations
A2: Pallabi Bhuyan | B2: Sustainable Energy Materials, Technical University Munich, Campus Straubing, Schulgasse 22, Straubing 94315, Germany
A3: Ran He | B3: IFW Dresden, Helmholtzstraße20, 01069, Dresden, Germany
A4: Yuanyuan Shi | B4: Institute of Chemical Research of Catalonia (ICIQ), The Barcelona Institute of Science and Technology (BIST), Tarragona, Spain | C4: Institute of Functional Nano & Soft Materials (FUNSOM), Collaborative Innovation Center of Suzhou Nanoscience and Technology, Suzhou, China
A5: A. Abbasi | B5: External Organizations | C5: Computational Phase Studies, Computational Materials Design, Max Planck Institute for Sustainable Materials, Max Planck Society | D5: Computational Phase Studies, Computational Materials Design, Max-Planck-Institut für Eisenforschung GmbH, Max Planck Society
A6: A. Abts | B6: Electrochemistry and Corrosion, Interface Chemistry and Surface Engineering, Max Planck Institute for Sustainable Materials, Max Planck Society | C6: Electrochemistry and Corrosion, Interface Chemistry and Surface Engineering, Max-Planck-Institut für Eisenforschung GmbH, Max Planck Society
A7: A. Al-Ashouri | B7: Young Investigator Group - Perovskite Tandem Solar Cells, Helmholtz-Zentrum Berlin
A8: A. Al-Sawalmih | B8: Biological Composites, Microstructure Physics and Alloy Design, Max Planck Institute for Sustainable Materials, Max Planck Society | C8: Biological Composites, Microstructure Physics and Alloy Design, Max-Planck-Institut für Eisenforschung GmbH, Max Planck Society | D8: External Organizations
A9: A. Alanen
A10: A. Alkauskas
A11: A. Ardehali Barani | B11: Alloy Design and Thermomechanical Processing, Microstructure Physics and Alloy Design, Max Planck Institute for Sustainable Materials, Max Planck Society | C11: Alloy Design and Thermomechanical Processing, Microstructure Physics and Alloy Design, Max-Planck-Institut für Eisenforschung GmbH, Max Planck Society | D11: External Organizations
A12: A. Babich
A13: A. Barani
A14: A. Bastos
A15: A. Bergmaier
A16: A. Beskrovnyi I | B16: Laboratory of Neutron Physics, Joint Institute for Nuclear Research, Dubna, Moscow District 141980, Russia
A17: A. Blümich | B17: SENTECH Instruments GmbH, D-12489 Berlin, Germany
A18: A. Brahme | B18: Microstructure Physics and Alloy Design, Max Planck Institute for Sustainable Materials, Max Planck Society | C18: Microstructure Physics and Alloy Design, Max-Planck-Institut für Eisenforschung GmbH, Max Planck Society | D18: External Organizations
A19: A. Butz
A20: A. Carmel Mary Esther | B20: Institut für Materialphysik, Westfälische Wilhelms-Universität Münster, Wilhelms, Germany
A21: A. Chakkedah
A22: A. Chakkedath
A23: A. Chakrabarti
A24: A. Cuitino
A25: A. Dannenberg
A26: A. De Nicolo
A27: A. DeBremaecker
A28: A. Di Prinzio
A29: A. Diaz Ortiz
A30: A. Diaz-Ortiz | B30: Max Planck Society
A31: A. Dlouhy
A32: A. Dreier
A33: A. Durairajan | B33: I3N-Aveiro, Department of Physics, University of Aveiro, Aveiro 3810 193, Portugal
A34: A. Dziakova
A35: A. Egan | B35: Center for Electron Microscopy and Analysis, The Ohio State University, Columbus, OH, 43212, USA | C35: Department of Materials Science and Engineering, The Ohio State University, Columbus, OH, 43210, USA_x000D_ _x000D_ View author publicati
A36: A. Eicke
A37: A. Eisenlohr | B37: Microstructure Physics and Alloy Design, Max Planck Institute for Sustainable Materials, Max Planck Society | C37: Microstructure Physics and Alloy Design, Max-Planck-Institut für Eisenforschung GmbH, Max Planck Society
A38: A. Ektarawong | B38: Thin Film Physics Division, Department of Physics, Chemistry and Biology (IFM), Linköping University, Linköping, Sweden
A39: A. Elsner | B39: Alloy Design and Thermomechanical Processing, Microstructure Physics and Alloy Design, Max Planck Institute for Sustainable Materials, Max Planck Society | C39: Alloy Design and Thermomechanical Processing, Microstructure Physics and Alloy Design, Max-Planck-Institut für Eisenforschung GmbH, Max Planck Society | D39: External Organizations
A40: A. Engström
...

Sheet MPI_Affiliations
A1: Microstructure Physics and Alloy Design, Max Planck Institute for Sustainable Materials, Max Planck Society | B1: Microstructure Physics and Alloy Design, Max Planck Institute for Sustainable Materials, Max Planck Society
A2: Microstructure Physics and Alloy Design, Max-Planck-Institut für Eisenforschung GmbH, Max Planck Society | B2: Microstructure Physics and Alloy Design, Max-Planck-Institut für Eisenforschung GmbH, Max Planck Society
A3: Atom Probe Tomography, Microstructure Physics and Alloy Design, Max Planck Institute for Sustainable Materials, Max Planck Society | B3: Atom Probe Tomography, Microstructure Physics and Alloy Design, Max Planck Institute for Sustainable Materials, Max Planck Society
A4: Atom Probe Tomography, Microstructure Physics and Alloy Design, Max-Planck-Institut für Eisenforschung GmbH, Max Planck Society | B4: Atom Probe Tomography, Microstructure Physics and Alloy Design, Max-Planck-Institut für Eisenforschung GmbH, Max Planck Society
A5: Theory and Simulation, Microstructure Physics and Alloy Design, Max-Planck-Institut für Eisenforschung GmbH, Max Planck Society | B5: Theory and Simulation, Microstructure Physics and Alloy Design, Max-Planck-Institut für Eisenforschung GmbH, Max Planck Society
A6: Theory and Simulation, Microstructure Physics and Alloy Design, Max Planck Institute for Sustainable Materials, Max Planck Society | B6: Theory and Simulation, Microstructure Physics and Alloy Design, Max Planck Institute for Sustainable Materials, Max Planck Society
A7: Electrocatalysis, Interface Chemistry and Surface Engineering, Max Planck Institute for Sustainable Materials, Max Planck Society | B7: Electrocatalysis, Interface Chemistry and Surface Engineering, Max Planck Institute for Sustainable Materials, Max Planck Society
A8: Electrocatalysis, Interface Chemistry and Surface Engineering, Max-Planck-Institut für Eisenforschung GmbH, Max Planck Society | B8: Electrocatalysis, Interface Chemistry and Surface Engineering, Max-Planck-Institut für Eisenforschung GmbH, Max Planck Society
A9: Corrosion, Interface Chemistry and Surface Engineering, Max Planck Institute for Sustainable Materials, Max Planck Society | B9: Corrosion, Interface Chemistry and Surface Engineering, Max Planck Institute for Sustainable Materials, Max Planck Society
A10: Corrosion, Interface Chemistry and Surface Engineering, Max-Planck-Institut für Eisenforschung GmbH, Max Planck Society | B10: Corrosion, Interface Chemistry and Surface Engineering, Max-Planck-Institut für Eisenforschung GmbH, Max Planck Society
A11: Interface Spectroscopy, Interface Chemistry and Surface Engineering, Max Planck Institute for Sustainable Materials, Max Planck Society | B11: Interface Spectroscopy, Interface Chemistry and Surface Engineering, Max Planck Institute for Sustainable Materials, Max Planck Society
A12: Interface Spectroscopy, Interface Chemistry and Surface Engineering, Max-Planck-Institut für Eisenforschung GmbH, Max Planck Society | B12: Interface Spectroscopy, Interface Chemistry and Surface Engineering, Max-Planck-Institut für Eisenforschung GmbH, Max Planck Society
... A20: Microscopy and Diffraction, Microstructure Physics and Alloy Design, Max-Planck-Institut für Eisenforschung GmbH, Max Planck Society | B20: Microscopy and Diffraction, Microstructure Physics and Alloy Design, Max-Planck-Institut für Eisenforschung GmbH, Max Planck Society
A21: Nano-/ Micromechanics of Materials, Structure and Nano-/ Micromechanics of Materials, Max Planck Institute for Sustainable Materials, Max Planck Society
A22: Nano-/ Micromechanics of Materials, Structure and Nano-/ Micromechanics of Materials, Max-Planck-Institut für Eisenforschung GmbH, Max Planck Society
A23: Advanced Transmission Electron Microscopy, Structure and Nano-/ Micromechanics of Materials, Max Planck Institute for Sustainable Materials, Max Planck Society
A24: Advanced Transmission Electron Microscopy, Structure and Nano-/ Micromechanics of Materials, Max-Planck-Institut für Eisenforschung GmbH, Max Planck Society
A25: Max Planck Society
A26: Computational Materials Design, Max-Planck-Institut für Eisenforschung GmbH, Max Planck Society
A27: Mechanism-based Alloy Design, Microstructure Physics and Alloy Design, Max Planck Institute for Sustainable Materials, Max Planck Society
A28: Mechanism-based Alloy Design, Microstructure Physics and Alloy Design, Max-Planck-Institut für Eisenforschung GmbH, Max Planck Society
A29: Electrochemistry and Corrosion, Interface Chemistry and Surface Engineering, Max Planck Institute for Sustainable Materials, Max Planck Society
A30: Electrochemistry and Corrosion, Interface Chemistry and Surface Engineering, Max-Planck-Institut für Eisenforschung GmbH, Max Planck Society
A31: Computational Materials Design, Max Planck Institute for Sustainable Materials, Max Planck Society
A32: Adhesion and Thin Films, Interface Chemistry and Surface Engineering, Max Planck Institute for Sustainable Materials, Max Planck Society
... A381: Sustainable Synthesis of Materials,Interdepartmental and Partner Groups, Max-Planck-Institut für Eisenforschung
